Workbook

Sheet 設定情報
A1: 見積基本情報
B2: 設定項目 | C2: 入力値 | D2: 備考 | G2: 代理店マスタ（メンテナンス可能）
A3: 1 | B3: 見積作成日 | C3: 45793 | H3: ライセンス | I3: 保守 | J3: 音声ライセンス | K3: ライセンス | L3: 保守
A4: 2 | B4: 代理店名 | C4: To: PT KDDI Indonesia | G4: Panasonic | H4: 0.6 | I4: 0.5 | J4: 0.65 | K4: At the end of next month of delivery date | L4: At the end of next month of delivery date
A5: 3 | B5: エンドユーザ名① | C5: For:PT Minda ASEAN Automotive | G5: KDDI | H5: 0.65 | I5: 0.8 | J5: 0.75 | K5: At the end of next month of delivery date | L5: At the end of next month of delivery date
A6: 4 | B6: エンドユーザ名② | D6: ※商流が長い場合、2行目に記載 （スペースを入れておく） | G6: DENTSU SOKEN | H6: 0.6 | I6: 0.7 | J6: 0.75 | K6: At the end of next month of delivery date | L6: At the end of next month of delivery date
A7: 5 | B7: 代理店種別 | C7: KDDI | G7: Tomas Tech | H7: 0.65 | I7: 0.8 | J7: 0.75 | K7: At the end of next month of delivery date | L7: At the end of next month of delivery date
A8: 6 | B8: ライセンス仕切率 | C8: =VLOOKUP($C$7,$G$4:$J$18,2,FALSE) -> 0.65 | D8: KDDI | G8: 大塚台湾 | H8: 0.6 | I8: 0.85 | J8: 0.75 | K8: At the end of next month of delivery date | L8: At the end of next month of delivery date
A9: 7 | B9: 保守仕切率 | C9: =VLOOKUP($C$7,$G$4:$J$18,3,FALSE) -> 0.8 | G9: SOLPAC | H9: 0.7 | I9: 0.8 | J9: 0.8 | K9: At the end of next month of delivery date | L9: At the end of next month of delivery date
A10: 8 | B10: 音声 保守仕切率 | G10: Design lab | H10: 0.7 | I10: 0.8 | J10: 0.8 | K10: At the end of next month of delivery date | L10: At the end of next month of delivery date
A11: 9 | B11: ライセンス支払い条件 | C11: =VLOOKUP($C$7,$G$4:$L$18,5,FALSE) -> At the end of next month of delivery date | G11: Peto | H11: 0.7 | I11: 0.9 | J11: 0.8 | K11: ライセンス証発行月末締め翌月末現金お支払い | L11: ライセンス証発行月末締め翌月末現金お支払い
A12: 10 | B12: 保守支払い条件 | C12: =VLOOKUP($C$7,$G$4:$L$18,6,FALSE) -> At the end of next month of delivery date | G12: AQM | H12: 0.7 | I12: 0.8 | J12: 0.8 | K12: ライセンス証発行月末締め翌月末現金お支払い | L12: ライセンス証発行月末締め翌月末現金お支払い
A13: 11 | B13: JOBNo | C13: S-25-00398 | D13: Kintonの営業管理Noを記入する | G13: D | H13: 0.7 | I13: 0.9 | J13: 0.8 | K13: ライセンス証発行月末締め翌月末現金お支払い | L13: ライセンス証発行月末締め翌月末現金お支払い
A14: 12 | B14: 枝番 | C14: 001 | G14: E | H14: 0.7 | I14: 0.9 | J14: 0.8 | K14: ライセンス証発行月末締め翌月末現金お支払い | L14: ライセンス証発行月末締め翌月末現金お支払い
A15: 13 | B15: 見積有効期限 | C15: ="End of "&YEAR(EDATE(C3,3))&"/"&MONTH(EDATE(C3,3))&" " -> End of 2025/8 | G15: F | H15: 0.7 | I15: 0.9 | J15: 0.8 | K15: ライセンス証発行月末締め翌月末現金お支払い | L15: ライセンス証発行月末締め翌月末現金お支払い
A16: オンプレ版 見積条件 | G16: G | H16: 0.7 | I16: 0.9 | J16: 0.8 | K16: ライセンス証発行月末締め翌月末現金お支払い | L16: ライセンス証発行月末締め翌月末現金お支払い
B17: 設定項目 | C17: 入力値 | D17: 備考 | G17: H | H17: 0.7 | I17: 0.9 | J17: 0.8 | K17: ライセンス証発行月末締め翌月末現金お支払い | L17: ライセンス証発行月末締め翌月末現金お支払い
A18: 1 | B18: ライセンス数 | C18: 100 | G18: I | H18: 0.7 | I18: 0.9 | J18: 0.8 | K18: ライセンス証発行月末締め翌月末現金お支払い | L18: ライセンス証発行月末締め翌月末現金お支払い
A19: 2 | B19: ライセンス費用 | C19: =VLOOKUP($C$18,$G$21:$K$42,2,FALSE) -> 3000000
A20: 3 | B20: 保守費用 | C20: =VLOOKUP($C$18,$G$21:$K$42,3,FALSE) -> 450000 | H20: パッケージ | I20: 保守
A21: 4 | B21: オプション有無① | C21: オプションなし | G21: 5 | H21: 1066000 | I21: =H21*15% -> 159900
A22: 5 | B22: オプション費用① | C22: =VLOOKUP($C$21,$G$44:$K$45,2,FALSE) -> #N/A | G22: 10 | H22: 1410000 | I22: =H22*15% -> 211500
A23: 6 | B23: 保守① | C23: =VLOOKUP($C$21,$G$44:$K$45,3,FALSE) -> #N/A | G23: 20 | H23: 1800000 | I23: =H23*15% -> 270000 | K23: =(H22+H44)*0.4+(I22+I44)*0.5 -> 1068750
B24: オプション有無② | C24: オプションなし | G24: 30 | H24: 2040000 | I24: =H24*15% -> 306000
B25: オプション費用② | C25: =VLOOKUP($C$24,$G$44:$K$46,2,FALSE) -> #N/A | F25: タクシーあり | G25: 40 | H25: 2280000 | I25: =H25*15% -> 342000
A26: 7 | B26: オプション有無③ | C26: 音声なし | F26: タクシーなし | G26: 50 | H26: 2400000 | I26: =H26*15% -> 360000
A27: 8 | B27: ライセンス数③ | C27: 5 | G27: 60 | H27: 2520000 | I27: =H27*15% -> 378000
A28: 9 | B28: 費用③ | C28: =IF(OR(C26="音声なし",C26="音声あり"),IF(C27="","",(VLOOKUP($C$27,$G$21:$K$42,2,FALSE)-600000))*0.4,VLOOKUP($C$26,$G$50:$H$53,2,FALSE)) -> 186400 | G28: 70 | H28: 2640000 | I28: =H28*15% -> 396000
A29: 10 | B29: 保守③ | C29: =IF(C28="","",C28*0.15) -> 27960 | G29: 80 | H29: 2760000 | I29: =H29*15% -> 414000
A30: 11 | B30: オプション有無④ | C30: IoTなし | G30: 90 | H30: 2880000 | I30: =H30*15% -> 432000
A31: 12 | B31: ライセンス④ | C31: 5 | G31: 100 | H31: 3000000 | I31: =H31*15% -> 450000
A32: 13 | B32: 費用④ | C32: =IF(OR(C30="音声なし",C30="音声あり"),IF(C31="","",(VLOOKUP($C$31,$G$21:$K$42,2,FALSE)-600000))*0.4,VLOOKUP($C$30,$G$50:$H$53,2,FALSE)) -> #N/A | G32: 150 | H32: 3540000 | I32: =H32*15% -> 531000
B33: 保守④ | C33: =IF(C32="","",C32*0.15) -> #N/A | G33: 200 | H33: 4080000 | I33: =H33*15% -> 612000
A34: 作業交通費 | G34: 250 | H34: 4344000 | I34: =H34*15% -> 651600
B35: 設定項目 | C35: 入力値 | D35: 備考 | G35: 300 | H35: 4608000 | I35: =H35*15% -> 691200
A36: 1 | B36: 最寄り駅 | C36: JR恵比寿駅 | D36: お客様最寄り駅を記入 | G36: 350 | H36: 4860000 | I36: =H36*15% -> 729000
A37: 2 | B37: 交通費（片道） | C37: 500 | G37: 400 | H37: 5112000 | I37: =H37*15% -> 766800
A38: 3 | B38: 宿泊数 | C38: 1 | G38: 450 | H38: 5364000 | I38: =H38*15% -> 804600
A39: 4 | B39: タクシー有無 | C39: タクシーなし | G39: 500 | H39: 5616000 | I39: =H39*15% -> 842400
A40: 5 | B40: タクシー費用 | C40: 1000
...

Sheet 表紙
A1: QUOTATION
C3: 2026-03-12 | D3: =設定情報!C3 -> 45793
C4: テスト代理店 | D4: ="Quotation No: "&設定情報!C13&"-"&設定情報!C14 -> Quotation No: S-25-00398-001
C5: テスト顧客HH
A6: =設定情報!C4&" " -> To: PT KDDI Indonesia
A11: Quotation Summary
A14: =設定情報!C5 -> For:PT Minda ASEAN Automotive
A15: =設定情報!C6
A18: No. | B18: Software name and specification | C18: 10 | F18: Payment Term
A19: Ⅰ． | B19: i-Reporter On-premise Package Version
A21: 1 | B21: =ライセンス!B22&" License" -> i-Reporter On-premise License Version License | C21: =ライセンス!A16 -> 1950000 | F21: T.B.C
B22: =ライセンス!B23 -> 100 user license（＝number of registration ID）
A24: 2 | B24: i-Reporter Annual Maintenance Fee | C24: =保守料!A16 -> 360000 | F24: T.B.C
C30: =SUM(C19:E29) -> 2310000
A45: Remarks）
A46: The following price is effective from January 1st,2026
A47: =IF(OR(設定情報!C7="Panasonic",設定情報!C7="Dentsu Soken"),"","Please cover the withholding tax at your side and arrange the payment with full amount of invoice.") -> Please cover the withholding tax at your side and arrange the payment with full amount of invoice.

Sheet ライセンス
A1: QUOTATION
E3: =表紙!$D$3 -> 45793
E4: =表紙!D4&"-01" -> Quotation No: S-25-00398-001-01
A6: =表紙!A6 -> To: PT KDDI Indonesia
A11: T.B.C
A12: ="Term of Payment ： "&設定情報!C11 -> Term of Payment ： At the end of next month of delivery date
A13: ="Validity ： "&設定情報!C15 -> Validity ： End of 2025/8
A16: =G51 -> 1950000
A18: Item | C18: Software name and specification | D18: Q'ty | E18: Unit | F18: Price | G18: Amount
B19: =表紙!A14 -> For:PT Minda ASEAN Automotive
B20: =表紙!A15
A21: 1 | B21: Basic Package
B22: i-Reporter On-premise License Version | D22: 1 | E22: set(s) | F22: =設定情報!C19 -> 3000000 | G22: =D22*F22 -> 3000000
B23: =" "&設定情報!C18&" user license（＝number of registration ID）" -> 100 user license（＝number of registration ID）
B24: <License configuration>
B25: 1 | C25: ConMas Server (Web Application and ConMas DB(PostgreSQL))
B26: 2 | C26: ConMas Manager (Web Application)
B27: 3 | C27: ConMas Designer（Windows Native Application）
B28: 4 | C28: iPad/iPhone App. / Windows App.
B29: ※iPad/iPhone App. is downloaded from AppStore as free of charge.
B30: ※Windows App. is downloaded from Support WEB.
B31: ※Log-in user ID and passward is required to use ConMas Manager, Designer, iPad, iPhone, and Windows App.
B32: ※No limitation for the number of installing ConMas Designer to Windows PC.
B33: ※No limitation for the number of installing App. of iPad/iPhone,Windows tablet.
A35: =IF(設定情報!C21="APIなし","",2) -> 2 | B35: Option Module
B36: =IF(設定情報!C21="オプションなし","",設定情報!C21) | D36: =IF(設定情報!C21="オプションなし","",1) | E36: =IF(設定情報!C21="オプションなし","","set") | F36: =IF(設定情報!C21="オプションなし","",設定情報!C22) | G36: =IF(設定情報!C21="オプションなし","",D36*F36)
B37: =IF(設定情報!C24="オプションなし","",設定情報!C24) | D37: =IF(設定情報!C24="オプションなし","",1) | E37: =IF(設定情報!C24="オプションなし","","set") | F37: =IF(設定情報!C24="オプションなし","",設定情報!C25) | G37: =IF(設定情報!C24="オプションなし","",D37*F37)
F38: Discount for partner | G38: =SUM(G19:G37)*-(1-設定情報!C8) -> -1050000
F39: =1-設定情報!C8 -> 0.35
A41: =IF(OR(設定情報!C26="音声なし",設定情報!C26="IoTなし"),"",3) | B41: =IF(OR(設定情報!C26="音声なし",設定情報!C26="IoTなし"),"","オプションモジュール")
B42: =IF(OR(設定情報!C26="音声なし",設定情報!C26="IoTなし"),"",IF(設定情報!C26="音声あり","音声入力オプション "&設定情報!C27&"ライセンス",設定情報!C26)) | D42: =IF(OR(設定情報!C26="音声なし",設定情報!C26="IoTなし"),"",1) | E42: =IF(OR(設定情報!C26="音声なし",設定情報!C26="IoTなし"),"","式") | F42: =IF(OR(設定情報!C26="音声なし",設定情報!C26="IoTなし"),"",設定情報!C28) | G42: =IF(OR(設定情報!C26="音声なし",設定情報!C26="IoTなし"),"",D42*F42)
B43: =IF(OR(設定情報!C30="音声なし",設定情報!C30="IoTなし"),"",IF(設定情報!C30="音声あり","音声入力オプション "&設定情報!C31&"ライセンス",設定情報!C30)) | D43: =IF(OR(設定情報!C30="音声なし",設定情報!C30="IoTなし"),"",1) | E43: =IF(OR(設定情報!C30="音声なし",設定情報!C30="IoTなし"),"","式") | F43: =IF(OR(設定情報!C30="音声なし",設定情報!C30="IoTなし"),"",設定情報!C32) | G43: =IF(OR(設定情報!C30="音声なし",設定情報!C30="IoTなし"),"",D43*F43)
F44: Discount for partner | G44: =IF(F42="","",SUM(G42:G43)*-0.2)
F45: =IF(F42="","","20%")
A51: G Total | G51: =SUM(G19:G50) -> 1950000
A52: Remarks）
A53: The following price is effective from January 1st,2026
A54: =IF(OR(設定情報!C7="Panasonic",設定情報!C7="Dentsu Soken"),"","Please cover the withholding tax at your side and arrange the payment with full amount of invoice.") -> Please cover the withholding tax at your side and arrange the payment with full amount of invoice.
E59: TAKASHI MIZUNO
E60: PRESIDENT & CEO

Sheet 保守料
A1: QUOTATION
E3: =表紙!$D$3 -> 45793
E4: =表紙!D4&"-02" -> Quotation No: S-25-00398-001-02
A6: =表紙!A6 -> To: PT KDDI Indonesia
A11: T.B.C
A12: ="Term of Payment ： "&設定情報!C12 -> Term of Payment ： At the end of next month of delivery date
A13: =ライセンス!A13 -> Validity ： End of 2025/8
A16: =G50 -> 360000
A18: Item | C18: Software name and specification | D18: Q'ty | E18: Unit | F18: Price | G18: Amount
B19: =ライセンス!B19 -> For:PT Minda ASEAN Automotive
B20: =ライセンス!B20
B21: i-Reporter Annual Maintenance Fee （From the first year）
B22: Software License Charge ×１５％
B23: Maintenance period：1 year from the date after 3 months of license delivery month.
B24: Annual maintenance fee must be paid with the license fee.
B25: Please place the order for the annual maintenance fee same timing with the software license.
A32: 1 | B32: =ライセンス!B21 -> Basic Package | D32: 1 | E32: Year | F32: =設定情報!C20 -> 450000 | G32: =D32*F32 -> 450000
B33: =ライセンス!B22 -> i-Reporter On-premise License Version
B34: =ライセンス!B23 -> 100 user license（＝number of registration ID）
A36: =IF(設定情報!C21="APIなし","",2) -> 2 | B36: =IF(設定情報!C21="APIなし","","Option Module") -> Option Module
B37: =IF(設定情報!C21="APIなし","","Web API Module Set (for external system coordination)") -> Web API Module Set (for external system coordination) | D37: =IF(設定情報!C21="オプションなし","",1) | E37: =IF(設定情報!C21="オプションなし","","set") | F37: =IF(設定情報!C21="オプションなし","",設定情報!C23) | G37: =IF(設定情報!C21="オプションなし","",D37*F37)
B38: =ライセンス!B37 | D38: =ライセンス!D37 | E38: =ライセンス!E37 | F38: =IF(設定情報!C24="オプションなし","",設定情報!C25*0.15) | G38: =IF(設定情報!C24="オプションなし","",D38*F38)
F39: Discount for partner | G39: =SUM(G20:G38)*-(1-設定情報!C9) -> -90000
F40: =1-設定情報!C9 -> 0.2
A43: =ライセンス!A41 | B43: =ライセンス!B41
B44: =ライセンス!B42 | D44: =ライセンス!D42 | E44: =ライセンス!E42 | F44: =IF($B44="","",ライセンス!F42*0.15) | G44: =IF($B44="","",D44*F44)
B45: =ライセンス!B43 | D45: =ライセンス!D43 | E45: =ライセンス!E43 | F45: =IF($B45="","",ライセンス!F43*0.15) | G45: =IF($B45="","",D45*F45)
F46: =IF($B46="","",ライセンス!F44*0.15) | G46: =IF($B46="","",D46*F46)
F47: =IF($B47="","",ライセンス!F45*0.15) | G47: =IF($B47="","",D47*F47)
A50: G. Total | G50: =SUM(G18:G49) -> 360000
A51: Remarks）
A52: The following price is effective from January 1st,2026
A53: =IF(OR(設定情報!C7="Panasonic",設定情報!C7="Dentsu Soken"),"","Please cover the withholding tax at your side and arrange the payment with full amount of invoice.") -> Please cover the withholding tax at your side and arrange the payment with full amount of invoice.
E58: TAKASHI MIZUNO
E59: PRESIDENT & CEO
